Workbook

Sheet Matriz Ckeck LIst
C3: MATRIZ PARA COMPROBACIÓN REQUERIMIENTOS DE CALIDAD DE PROYECTO ACADEMICO
D5: SISTEMA: | E5: Sistema de Gestión de Aforo (SGA)
F6: Requerimientos Funcionales
B7: Nº | C7: CRITERIOS DE CALIDAD (Documento/Requerimientos) | E7: Status Nivel de Acuerdo | F7: RF1 Capturar y sincronizar presencia | G7: Status Nivel de Acuerdo | H7: 100 | I7: RF2 Monitorear del aforo en tiempo real | J7: Status Nivel de Acuerdo | K7: RF3 Recibir notificaciones de aforo
H8: 0
B9: 1 | C9: Agreed | E9: OK | F9: 1. Entrevistas a los actores 2. Minuta de la entrevista 3. Aceptación del prototipo no funcional por videoconferencia | G9: OK | H9: 1 | I9: 1. Entrevistas a los actores 2. Minuta de la entrevista 3. Aceptación del prototipo no funcional por videoconferencia | J9: OK | K9: 1. Entrevistas a los actores 2. Minuta de la entrevista 3. Aceptación del prototipo no funcional por videoconferencia
B10: 2 | C10: Ranked | E10: OK | F10: 1. En la descripción del caso de Uso se especifica la prioridad Alta | G10: OK | I10: 1. En la descripción del caso de Uso se especifica la prioridad Alta | J10: OK | K10: 1. En la descripción del caso de Uso se especifica la prioridad Alta
B11: 3 | C11: Unambiguos | E11: OK | F11: 1. Redacción en lenguaje claro. 2. El tutor y el equipo interpretan de igual manera el caso de uso | G11: OK | I11: 1. Redacción en lenguaje claro. 2. El tutor y el equipo interpretan de igual manera el caso de uso | J11: OK | K11: 1. Redacción en lenguaje claro. 2. El tutor y el equipo interpretan de igual manera el caso de uso
B12: 4 | C12: Valid and up-to date | E12: OK | F12: 1. Toda nueva información ha sido incorporada, se han incorporado los últimos cambios pedidos luego del feedback realizado por el cliente | G12: NOK | I12: 1. No se han incorporado los últimos cambios pedidos luego del feedback realizado por el cliente | J12: OK | K12: 1. No se han incorporado los últimos cambios cambios tras el feedback realizado por el cliente
B13: 5 | C13: Correct | E13: OK | F13: 1. Está alineado con los objetivos del sistema. 2. Refleja lo que realmente necesita el cliente. | G13: OK | I13: 1. Está alineado con los objetivos del sistema. 2. Refleja lo que realmente necesita el cliente. | J13: OK | K13: 1. Está alineado con los objetivos del sistema. 2. Refleja lo que realmente necesita el cliente.
B14: 6 | C14: Consisten | E14: OK | F14: 1. Documentación basada en modelos: Diagrama de Casos de Uso 2. Usa términos definidos previamente. | G14: OK | I14: 1. Documentación basada en modelos: Diagrama de Casos de Uso 2. Usa términos definidos previamente. 3. Palabras repetitivas. | J14: OK | K14: 1. Documentación basada en modelos: Diagrama de Casos de Uso 2. Usa términos definidos previamente. 3. Palabras repetitivas.
B15: 7 | C15: Verifiable | E15: OK | F15: 1. Requisito Medible 2. Falta Casos de Prueba | G15: OK | I15: 1. Requisito Medible 2. Falta Casos de Prueba | J15: OK | K15: 1. Requisito Medible 2. Falta Casos de Prueba
B16: 8 | C16: Realizable | E16: OK | F16: 1. Funcionalidad tomada en cuenta dentro de la estimación del costo del proyecto (900$) 2. No se ha desarrollado | G16: NOK | I16: 1. Funcionalidad tomada en cuenta dentro de la estimación del costo del proyecto (900$) 2. No se ha desarrollado | J16: OK | K16: 1. Funcionalidad tomada en cuenta dentro de la estimación del costo del proyecto (900$) 2. No se ha desarrollado
B17: 9 | C17: Traceable | E17: OK | F17: 1. Es claro el origen del requisito y sus relaciones con otros requisitos (matriz de trazabilidad cliente/casos de uso y casos de uso/casos de uso) 2. Cuenta con un identificador único | G17: OK | I17: 1. Es claro el origen del requisito y sus relaciones con otros requisitos (matriz de trazabilidad cliente/casos de uso y casos de uso/casos de uso) 2. Cuenta con un identificador único | J17: OK | K17: 1. Es claro el origen del requisito y sus relaciones con otros requisitos (matriz de trazabilidad cliente/casos de uso y casos de uso/casos de uso) 2. Cuenta con un identificador único
B18: 10 | C18: Complete | E18: OK | F18: 1. Contiene toda la información necesaria (entradas, salidas, precondiciones, postcondiciones) para entender y diseñar la función. 2. Describe completamente la funcionalidad esperada. | G18: OK | I18: 1. Contiene toda la información necesaria (entradas, salidas, precondiciones, postcondiciones) para entender y diseñar la función. 2. Describe completamente la funcionalidad esperada. | J18: OK | K18: 1. Contiene toda la información necesaria (entradas, salidas, precondiciones, postcondiciones) para entender y diseñar la función. 2. Describe completamente la funcionalidad esperada.
B19: 11 | C19: Understandability | E19: OK | F19: 1. Se involucra al cliente 2. Existe glosario de términos | G19: OK | I19: 1. Se involucra al cliente 2.Uso de términos respaldado por un glosario de términos | J19: OK | K19: 1. Se involucra al cliente 2.Uso de términos respaldado por un glosario de términos
B27: Nº | C27: CRITERIOS DE CALIDAD (Documento/Requerimientos) | E27: Status Nivel de Acuerdo | F27: RF1 Capturar y sincronizar presencia
B29: 1 | C29: Agreed | E29: OK | F29: 1. Entrevistas a los actores 2. Minuta de la entrevista 3. Aceptación del prototipo no funcional por videoconferencia
B30: 2 | C30: Ranked | E30: OK | F30: 1. En la descripción del caso de Uso se especifica la prioridad Alta
B31: 3 | C31: Unambiguos | E31: OK | F31: 1. Redacción en lenguaje claro. 2. El tutor y el equipo interpretan de igual manera el caso de uso
B32: 4 | C32: Valid and up-to date | E32: OK | F32: 1. Toda nueva información ha sido incorporada, se han incorporado los últimos cambios pedidos luego del feedback realizado por el cliente
B33: 5 | C33: Correct | E33: OK | F33: 1. Está alineado con los objetivos del sistema. 2. Refleja lo que realmente necesita el cliente.
B34: 6 | C34: Consisten | E34: OK | F34: 1. Documentación basada en modelos: Diagrama de Casos de Uso 2. Usa términos definidos previamente.
B35: 7 | C35: Verifiable | E35: OK | F35: 1. Requisito Medible 2. Falta Casos de Prueba
B36: 8 | C36: Realizable | E36: OK | F36: 1. Funcionalidad tomada en cuenta dentro de la estimación del costo del proyecto (900$) 2. No se ha desarrollado
B37: 9 | C37: Traceable | E37: OK | F37: 1. Es claro el origen del requisito y sus relaciones con otros requisitos (matriz de trazabilidad cliente/casos de uso y casos de uso/casos de uso) 2. Cuenta con un identificador único
B38: 10 | C38: Complete | E38: OK | F38: 1. Contiene toda la información necesaria (entradas, salidas, precondiciones, postcondiciones) para entender y diseñar la función. 2. Describe completamente la funcionalidad esperada.
B39: 11 | C39: Understandability | E39: OK | F39: 1. Se involucra al cliente 2. Existe glosario de términos
B42: Nº | C42: CRITERIOS DE CALIDAD (Documento/Requerimientos) | E42: Status Nivel de Acuerdo | F42: RF2 Monitorear del aforo en tiempo real
B44: 1 | C44: Agreed | E44: OK | F44: 1. Entrevistas a los actores 2. Minuta de la entrevista 3. Aceptación del prototipo no funcional por videoconferencia
B45: 2 | C45: Ranked | E45: OK | F45: 1. En la descripción del caso de Uso se especifica la prioridad Alta
B46: 3 | C46: Unambiguos | E46: OK | F46: 1. Redacción en lenguaje claro. 2. El tutor y el equipo interpretan de igual manera el caso de uso
B47: 4 | C47: Valid and up-to date | E47: NOK | F47: 1. No se han incorporado los últimos cambios pedidos luego del feedback realizado por el cliente
B48: 5 | C48: Correct | E48: OK | F48: 1. Está alineado con los objetivos del sistema. 2. Refleja lo que realmente necesita el cliente.
B49: 6 | C49: Consisten | E49: OK | F49: 1. Documentación basada en modelos: Diagrama de Casos de Uso 2. Usa términos definidos previamente. 3. Palabras repetitivas.
B50: 7 | C50: Verifiable | E50: OK | F50: 1. Requisito Medible 2. Falta Casos de Prueba
B51: 8 | C51: Realizable | E51: NOK | F51: 1. Funcionalidad tomada en cuenta dentro de la estimación del costo del proyecto (900$) 2. No se ha desarrollado
B52: 9 | C52: Traceable | E52: OK | F52: 1. Es claro el origen del requisito y sus relaciones con otros requisitos (matriz de trazabilidad cliente/casos de uso y casos de uso/casos de uso) 2. Cuenta con un identificador único
B53: 10 | C53: Complete | E53: OK | F53: 1. Contiene toda la información necesaria (entradas, salidas, precondiciones, postcondiciones) para entender y diseñar la función. 2. Describe completamente la funcionalidad esperada.
B54: 11 | C54: Understandability | E54: OK | F54: 1. Se involucra al cliente 2.Uso de términos respaldado por un glosario de términos
...

Sheet MODELO LISTA DE COMPROBACION 1 
B1: SISTEMA: | C1: Sistema de Gestión de Aforo)
B2: FECHA: | C2: 46227
B3: AUTOR: | C3: Enrique Ortega
B4: REQUERIMIENTOS EVALUADOS : | C4: RF1 Capturar y sincronizar presencia
A6: CONTENIDO
A7: No. | B7: Pregunta | C7: SI | D7: NO
A8: 1 | B8: Todos los requerimientos relevantes se han documentado? | C8: X
A9: 2 | B9: Se han implementado las funciones requeridas? | C9: x
A10: 3 | B10: Existe algún mecanismo que permita seguir el impacto de dicho requerimiento a lo largo del resto de las actividades del ciclo productivo.? | C10: X
A11: 4 | B11: El origen de cada requerimento individual está claro ? | C11: X
A12: 5 | B12: Que tan facil es devolverse a los requerimientos? | C12: X
A13: 6 | B13: Los requerimientos reflejan las necesidades y deseos del cliente? | C13: X
A14: 7 | B14: No hay contradicciones entre los requerimientos? | D14: X
A15: 8 | B15: El requerimiento que se esta especificando contribuye a alcanzar un objetivo definido ? | C15: X
A16: 9 | B16: Existe un proceso acotado (en plazo y presupuesto) que permita determinar que el sistema construido satisface lo descrito en el propio requerimiento? | D16: x
A17: SUMATORIA: | C17: =COUNTA('MODELO LISTA DE COMPROBACION 1 '!$C$8:$C$16) -> 7 | D17: =COUNTA('MODELO LISTA DE COMPROBACION 1 '!$D$8:$D$16) -> 2
A18: PORCENTAJE : | C18: =C17/9 -> 0.77777778 | D18: =D17/9 -> 0.22222222
A20: DOCUMENTACIÓN
A21: No. | B21: Pregunta | C21: SI | D21: NO
A22: 1 | B22: Aplica un estandar para la documetación de requerimiento? | C22: X
A23: 2 | B23: Cumple con la estructura definida por el estandar? | C23: X
A24: 3 | B24: Utiliza un Glosario de términos normalizado? | C24: X
A25: 4 | B25: Los requerimientos Funcionales estan sujetos a una única interpretación? | C25: X
A26: 5 | B26: El modelo aplicado cumple con la sintaxis? | C26: X
A27: SUMATORIA: | C27: =COUNTA('MODELO LISTA DE COMPROBACION 1 '!$C$22:$C$26) -> 5 | D27: =COUNTA('MODELO LISTA DE COMPROBACION 1 '!$D$22:$D$26) -> 0
A28: PORCENTAJE : | C28: =C27/5 -> 1 | D28: =D27/5 -> 0
A30: NIVEL DE ACUERDO
A31: No. | B31: Pregunta | C31: SI | D31: NO
A32: 1 | B32: Todos los requerimientos han sido acordados con todos los interesados? | D32: x
A33: 2 | B33: Todos los requerimientos modificados han sido acordados por todos los implicados? | C33: X
A34: 3 | B34: Han sido resueltos todos los conflictos conocidos respectos de los requerimientos? | C34: X
A35: SUMATORIA: | C35: =COUNTA('MODELO LISTA DE COMPROBACION 1 '!$C$32:$C$34) -> 2 | D35: =COUNTA('MODELO LISTA DE COMPROBACION 1 '!$D$32:$D$34) -> 1
A36: PORCENTAJE : | C36: =C35/3 -> 0.66666667 | D36: =D35/3 -> 0.33333333
A40: RESUMEN
B41: CONTENIDO | C41: 89
B42: DOCUMENTACIÓN | C42: 100
B43: NIVEL DE ACUERDO | C43: 100

Sheet MODELO LISTA DE COMPROBACION 2
B1: SISTEMA: | C1: Sistema De Gestion de aforo
B2: FECHA: | C2: 46301
B3: AUTOR: | C3: Josue Chango
B4: REQUERIMIENTOS EVALUADOS : | C4: RF2 Monitoreo del aforo en tiempo real
A6: CONTENIDO
A7: No. | B7: Pregunta | C7: SI | D7: NO
A8: 1 | B8: Todos los requerimientos relevantes se han documentado? | C8: X
A9: 2 | B9: Se han implementado las funciones requeridas? | C9: X
A10: 3 | B10: Existe algún mecanismo que permita seguir el impacto de dicho requerimiento a lo largo del resto de las actividades del ciclo productivo.? | C10: X
A11: 4 | B11: El origen de cada requerimento individual está claro ? | C11: X
A12: 5 | B12: Que tan facil es devolverse a los requerimientos? | C12: X
A13: 6 | B13: Los requerimientos reflejan las necesidades y deseos del cliente? | C13: X
A14: 7 | B14: No hay contradicciones entre los requerimientos? | C14: x
A15: 8 | B15: El requerimiento que se esta especificando contribuye a alcanzar un objetivo definido ? | C15: X
A16: 9 | B16: Existe un proceso acotado (en plazo y presupuesto) que permita determinar que el sistema construido satisface lo descrito en el propio requerimiento? | D16: X
A17: SUMATORIA: | C17: =COUNTA('MODELO LISTA DE COMPROBACION 2'!$C$8:$C$16) -> 8 | D17: =COUNTA('MODELO LISTA DE COMPROBACION 2'!$D$8:$D$16) -> 1
A18: PORCENTAJE : | C18: =C17/9 -> 0.88888889 | D18: =D17/9 -> 0.11111111
A20: DOCUMENTACIÓN
A21: No. | B21: Pregunta | C21: SI | D21: NO
A22: 1 | B22: Aplica un estandar para la documetación de requerimiento? | C22: X
A23: 2 | B23: Cumple con la estructura definida por el estandar? | C23: X
A24: 3 | B24: Utiliza un Glosario de términos normalizado? | C24: X
A25: 4 | B25: Los requerimientos Funcionales estan sujetos a una única interpretación? | D25: X
A26: 5 | B26: El modelo aplicado cumple con la sintaxis? | C26: X
A27: SUMATORIA: | C27: =COUNTA('MODELO LISTA DE COMPROBACION 2'!$C$22:$C$26) -> 4 | D27: =COUNTA('MODELO LISTA DE COMPROBACION 2'!$D$22:$D$26) -> 1
A28: PORCENTAJE : | C28: =C27/5 -> 0.8 | D28: =D27/5 -> 0.2
A30: NIVEL DE ACUERDO
A31: No. | B31: Pregunta | C31: SI | D31: NO
A32: 1 | B32: Todos los requerimientos han sido acordados con todos los interesados? | D32: x
A33: 2 | B33: Todos los requerimientos modificados han sido acordados por todos los implicados? | D33: x
A34: 3 | B34: Han sido resueltos todos los conflictos conocidos respectos de los requerimientos? | C34: X
A35: SUMATORIA: | C35: =COUNTA('MODELO LISTA DE COMPROBACION 2'!$C$32:$C$34) -> 1 | D35: =COUNTA('MODELO LISTA DE COMPROBACION 2'!$D$32:$D$34) -> 2
A36: PORCENTAJE : | C36: =C35/3 -> 0.33333333 | D36: =D35/3 -> 0.66666667
A40: RESUMEN
B41: CONTENIDO | C41: 89
B42: DOCUMENTACIÓN | C42: 100
B43: NIVEL DE ACUERDO | C43: 100

Sheet MODELO DE LISTA DE COMPROBACION
B1: SISTEMA: | C1: Sistema de Gestión de Aforo (SGA)
B2: FECHA: | C2: 46227
B3: AUTOR: | C3: Josué Guayasamín
B4: REQUERIMIENTOS EVALUADOS : | C4: RF3 Recibir notificaciones de aforo
A6: CONTENIDO
A7: No. | B7: Pregunta | C7: SI | D7: NO
A8: 1 | B8: Todos los requerimientos relevantes se han documentado? | C8: X
A9: 2 | B9: Se han implementado las funciones requeridas? | C9: X
A10: 3 | B10: Existe algún mecanismo que permita seguir el impacto de dicho requerimiento a lo largo del resto de las actividades del ciclo productivo.? | C10: X
A11: 4 | B11: El origen de cada requerimento individual está claro ? | C11: X
A12: 5 | B12: Que tan facil es devolverse a los requerimientos? | C12: X
A13: 6 | B13: Los requerimientos reflejan las necesidades y deseos del cliente? | C13: X
A14: 7 | B14: No hay contradicciones entre los requerimientos? | D14: X
A15: 8 | B15: El requerimiento que se esta especificando contribuye a alcanzar un objetivo definido ? | C15: X
A16: 9 | B16: Existe un proceso acotado (en plazo y presupuesto) que permita determinar que el sistema construido satisface lo descrito en el propio requerimiento? | D16: X
A17: SUMATORIA: | C17: =COUNTA('MODELO DE LISTA DE COMPROBACION'!$C$8:$C$16) -> 7 | D17: =COUNTA('MODELO DE LISTA DE COMPROBACION'!$D$8:$D$16) -> 2
A18: PORCENTAJE : | C18: =C17/9 -> 0.77777778 | D18: =D17/9 -> 0.22222222
A20: DOCUMENTACIÓN
A21: No. | B21: Pregunta | C21: SI | D21: NO
A22: 1 | B22: Aplica un estandar para la documetación de requerimiento? | C22: X
A23: 2 | B23: Cumple con la estructura definida por el estandar? | D23: x
A24: 3 | B24: Utiliza un Glosario de términos normalizado? | C24: X
A25: 4 | B25: Los requerimientos Funcionales estan sujetos a una única interpretación? | D25: x
A26: 5 | B26: El modelo aplicado cumple con la sintaxis? | C26: X
A27: SUMATORIA: | C27: =COUNTA('MODELO DE LISTA DE COMPROBACION'!$C$22:$C$26) -> 3 | D27: =COUNTA('MODELO DE LISTA DE COMPROBACION'!$D$22:$D$26) -> 2
A28: PORCENTAJE : | C28: =C27/5 -> 0.6 | D28: =D27/5 -> 0.4
A30: NIVEL DE ACUERDO
A31: No. | B31: Pregunta | C31: SI | D31: NO
A32: 1 | B32: Todos los requerimientos han sido acordados con todos los interesados? | D32: x
A33: 2 | B33: Todos los requerimientos modificados han sido acordados por todos los implicados? | D33: X
A34: 3 | B34: Han sido resueltos todos los conflictos conocidos respectos de los requerimientos? | C34: X
A35: SUMATORIA: | C35: =COUNTA('MODELO DE LISTA DE COMPROBACION'!$C$32:$C$34) -> 1 | D35: =COUNTA('MODELO DE LISTA DE COMPROBACION'!$D$32:$D$34) -> 2
A36: PORCENTAJE : | C36: =C35/3 -> 0.33333333 | D36: =D35/3 -> 0.66666667
A40: RESUMEN
B41: CONTENIDO | C41: 78
B42: DOCUMENTACIÓN | C42: 100
B43: NIVEL DE ACUERDO | C43: 33

Sheet RECOMENDACIONES - 1
A1: PREGUNTA | B1: RECOMENDACIÓN
A2: ¿Se ejecutan revisiones constantes del modelo lógico y se actualiza la matriz de trazabilidad para evitar contradicciones operativas? | B2: Se recomienda ejecutar revisiones constantes del modelo lógico y mantener la matriz de trazabilidad para evitar las contradicciones operativas.
A3: ¿Se ha implementado un plan de aseguramiento de calidad que incluya hitos técnicos precisos y recursos financieros preasignados para verificar la implementación? | B3: Se sugiere implentar un plan de aseguramiento de calidad con hitos técnicos precisos y recursos financieros preasignados para verificar la implementación.
A4: ¿Se ha redactado y firmado un acta de aceptación con los interesados para formalizar el alcance del proyecto? | B4: Se sugiere escribir un acta de aceptación con los interesados para formalizar el alcance del proyecto.

Sheet RECOMENDACIONES - 2
A1: PREGUNTA | B1: RECOMENDACIÓN
A2: ¿Existe control de versiones e historial de cambios del documento? | B2: Se recomienda agregar al SRS una tabla de historial de cambios con las columnas Version, Fecha, Autor, Requisito afectado, Descripcion del cambio y Motivo, y trasladar ahi las notas CORRECCION, ACTUALIZACION y RESTAURADO hoy embebidas en el campo de Justificacion
A3: ¿Las referencias internas apuntan a requisitos vigentes? | B3: Se recomienda realizar sesiones de validación y consenso con todos los interesados clave antes de cerrar la especificación de requerimientos, esto asegurará que los requerimientos reflejen las necesidades puntuales.
A4: ¿Se ha estimado el esfuerzo, el costo y el plazo necesarios para realizar RF-1.1 a RF-1.10 (criterio Realizable)? | B4: Se recomienda incorporar una tabla de estimacion por cada requisito y un cronograma de alto nivel, incluyendo la Prueba de Concepto de campo como hito previo.
A5: ¿Se han implementado las funciones requeridas? | B5: Se recomienda incorporar al plan del proyecto una fase de implementacion y verificacion por modulo, asociando a cada requisito a sus criterios de aceptacion como casos de prueba con estado de ejecucion
A6: ¿Los requerimientos funcionales estan sujetos a una unica interpretacion? | B6: Se recomienda agregar a cada requisito una tabla de precondiciones y postcondiciones, con los estados validos y el esquema de la entidad de sesion de aforo

Sheet RECOMENDACIONES - 3
A2: ¿Qué conflicto técnico se identificó entre los disparadores de notificaciones (`RF-3.1`, `RF-3.2`, `RF-3.3`) al ser parametrizables por el administrador, y cómo debemos evitarlo? | B2: Debemos implementar validaciones lógicas en la interfaz web de parametrización (RF-8.2) que impidan físicamente al Gerente guardar un umbral de descongestión que sea mayor o igual al umbral de saturación u horas pico. De esta forma, evitamos que configuraciones erróneas del usuario generen bucles o notificaciones contradictorias en el servidor.
A3: ¿Qué omisión de estructura cometimos en la documentación de la regla anti-spam (`RF-3.4`) y la sugerencia de horarios (`RF-3.5`), y cómo debemos corregirla? | B3: Debemos redactar e incorporar formalmente en el SRS los Criterios de Aceptación en formato Dado / Cuando / Entonces (Given / When / Then) para `RF-3.4` (verificando el límite de máximo 2 notificaciones/día con espacio de 2 horas) y `RF-3.5`. Ningún requisito del Módulo 3 debe quedar solo con descripción narrativa.
A4: ¿Qué ambigüedad semántica o matemática existe entre la descripción de la notificación de afluencia (`RF-3.1`) y su criterio de aceptación `CA-01`? | B4: Debemos estandarizar la regla matemática de disparo en todo el documento, decidiéndonos por una sola expresión (`≥ 80%` o > 80%`). Es necesario corregir el texto para que tanto la descripción narrativa como el escenario de prueba utilicen exactamente la misma condición sin margen de duda para el programador o el tester.
A5: ¿Qué riesgo de aceptación existe al haber diseñado la frecuencia de notificaciones push sin consultar directamente el nivel de tolerancia de los socios del gimnasio? | B5: Debemos añadir en la App Móvil una pantalla de preferencias de notificación (canales opt-in / opt-out ) para que el cliente tenga el control de activar o desactivar las alertas proactivas, y realizar una prueba piloto (User Acceptance Testing) con un grupo reducido de socios para medir la tasa de rechazo antes del lanzamiento masivo.
